Workbook

Sheet 使い方
A1: GRS が利用者に出すメッセージの要否（記入用）
A2: 測った commit: 572da133（2026-10-08）。測り方は docs/review/message-review-2026-10-07.md の『調べ方』と同じ。
A3: JDG-1553「エラーメッセージ/ワーニングメッセージが多すぎる。一覧表を出せ」と DFC-2166 / PND-787 に答える表。
A5: 記入のしかた
A6: 1. シート『記入』を開く。黄色の 2 列（要否・コメント）だけを書く。ほかの列は変えない。
A7: 2. 『要否』には推奨を先に入れてある。賛成なら触らない。変えたい行だけ、セルの ▼ から選び直す。
A8: 3. 『文面を直す』を選んだ行は、コメントに直した文を書く（推奨の理由に案があれば、それでよければ『案のとおり』）。
A9: 4. 迷う行・問いがある行はコメントに書く。空でよい。
A10: 5. 見出しの ▼ で、まとまり・深刻度・OK・状況ごとに絞り込める。
A11: 6. 終わったら上書き保存（Ctrl+S）し、チャットで『埋めた』と伝える。ファイル名・場所・シート名は変えない。
A13: 要否の 5 つの意味
A14: 表示する（今のまま）: 今の出し方のまま残す。
... A26: 要否の数（記入に合わせて自動で数え直す）
A27: 要否 | B27: 推奨 | C27: 記入
A28: 表示する（今のまま） | B28: =COUNTIF(記入!$P$2:$P$139,A28) -> 66 | C28: =COUNTIF(記入!$N$2:$N$139,A28) -> 63
A29: 表示しない | B29: =COUNTIF(記入!$P$2:$P$139,A29) -> 14 | C29: =COUNTIF(記入!$N$2:$N$139,A29) -> 22
A30: OK を押さずに自然に消える表示にする | B30: =COUNTIF(記入!$P$2:$P$139,A30) -> 15 | C30: =COUNTIF(記入!$N$2:$N$139,A30) -> 12
A31: 1 枚にまとめる（同じまとまりの他の行と） | B31: =COUNTIF(記入!$P$2:$P$139,A31) -> 17 | C31: =COUNTIF(記入!$N$2:$N$139,A31) -> 15
A32: 文面を直す（コメントに案） | B32: =COUNTIF(記入!$P$2:$P$139,A32) -> 26 | C32: =COUNTIF(記入!$N$2:$N$139,A32) -> 26
A33: 計 | B33: =SUM(B28:B32) -> 138 | C33: =SUM(C28:C32) -> 138
A34: 推奨と違う行の数 | C34: =SUMPRODUCT(--(記入!$N$2:$N$139<>記入!$P$2:$P$139)) -> 11

Sheet 記入
A1: # | B1: ID | C1: 領域 | D1: 深刻度 | E1: OK | F1: まとまり | G1: 状況 | H1: 出る場面 | I1: 文（日本語） | J1: 次の一手（日本語） | K1: English | L1: 推奨の理由 | M1: 作法 | N1: 要否（記入） | O1: コメント（記入） | P1: 推奨（参照・変えない） | Q1: 備考 | R1: 出す所（src）
A2: 1 | B2: RS-4 | C2: ファイル読込（開く・取り込み・起動時） | D2: エラー | E2: 要 | F2: D | G2: 既存 | H2: ヘッダーの『開く』で選んだ（またはドロップした）ファイルが UTF-8 でない（例: Shift_JIS で保存した MSPDI XML）とき | I2: このファイルは UTF-8 ではないので読めません | J2: UTF-8 で保存し直してから開いてください | K2: This file is not UTF-8, so it cannot be read → Save it as UTF-8 and open it again | L2: 開けなかった理由と直し方は画面のどこにも出ないので、告げないと利用者は何もできない | M2: NT-1 | N2: 表示する（今のまま） | P2: 表示する（今のまま） | Q2: 開く操作が丸ごと止まる。ほかの読込通知とは重ならない | R2: src/framework/single-html-shell/frame-loop.ts:2833（raiseFileFault、対応表 881 notUtf8）
A3: 2 | B3: RS-11 | C3: ファイル読込（開く・取り込み・起動時） | D3: エラー | E3: 要 | F3: D | G3: 既存 | H3: ヘッダーの『開く』で、拡張子が .json / .xml / .html のどれでもないファイルを選んだとき | I3: 拡張子が、読み取れる形式のどれにも当てはまりません | J3: 読み取れる形式のファイルを選んでください | K3: The file name extension matches no format that can be read → Choose a file in a format that can be read | L3: 利用者には拡張子と中身の違いは要らない。RS-11/12/13 を「このファイルは GRS が読める形式（GRS JSON・MSPDI XML・GRS の .html）ではありません → 形式とファイルが壊れていないかを確かめてください」の 1 文にまとめる | M3: NT-1 | N3: 1 枚にまとめる（同じまとまりの他の行と） | P3: 1 枚にまとめる（同じまとまりの他の行と） | Q3: RS-12・RS-13 と 3 つで「形式が分からない」を言い分けている | R3: src/framework/single-html-shell/document-file-flow.ts:673（対応表 98 extension）
A4: 3 | B4: RS-12 | C4: ファイル読込（開く・取り込み・起動時） | D4: エラー | E4: 要 | F4: D | G4: 既存 | H4: ヘッダーの『開く』で、拡張子は .json などなのに中身の先頭がどの形式にも当たらない（壊れた・空の）ファイルを選んだとき | I4: ファイルの中身が、読み取れる形式のどれにも当てはまりません | J4: ファイルが壊れていないかを確かめてください | K4: The contents match no format that can be read → Check whether the file is intact | L4: RS-11 と同じ 1 文にまとめる（言い分けても利用者の次の一手は同じ） | M4: NT-1 | N4: 1 枚にまとめる（同じまとまりの他の行と） | P4: 1 枚にまとめる（同じまとまりの他の行と） | R4: src/framework/single-html-shell/document-file-flow.ts:673（対応表 99 firstCharacter）
A5: 4 | B5: RS-13 | C5: ファイル読込（開く・取り込み・起動時） | D5: エラー | E5: 要 | F5: D | G5: 既存 | H5: ヘッダーの『開く』で、拡張子は .json なのに中身が XML（またはその逆）のファイルを選んだとき | I5: 拡張子と中身が別の形式を指しているので、どちらとしても読めません | J5: ファイル名と中身のどちらが正しいかを確かめてください | K5: The extension and the contents name different formats, so neither can be read → Check which of the name and the contents is right | L5: RS-11 と同じ 1 文にまとめる | M5: NT-1 | N5: 1 枚にまとめる（同じまとまりの他の行と） | P5: 1 枚にまとめる（同じまとまりの他の行と） | R5: src/framework/single-html-shell/document-file-flow.ts:673（対応表 100 both）
A6: 5 | B6: RS-67 | C6: ファイル読込（開く・取り込み・起動時） | D6: エラー | E6: 要 | F6: D | G6: 既存 | H6: ヘッダーの『開く』で GRS が書き出したものではない .html を選んだとき、または文書の容れ物が 2 つ以上ある .html を起動したとき | I6: このファイルは GRS で開ける .html ではありません | J6: GRS のヘッダーの書き出しで作ったファイルか、ファイルの出どころを確かめてください | K6: This file is not an .html that GRS can open → Check that it was written out from the GRS header, or where the file came from | L6: 開かなかった理由が画面からは読めない。出どころを確かめる手がかりが要る | M6: NT-1 | N6: 表示する（今のまま） | P6: 表示する（今のまま） | R6: src/framework/single-html-shell/document-file-flow.ts:317（acceptedIntake）／起動時 single-html-shell.ts:286
A7: 6 | B7: RS-25 | C7: ファイル読込（開く・取り込み・起動時） | D7: エラー | E7: 要 | F7: D | G7: 既存 | H7: GRS JSON の列が決められた形に合わないファイルを読んだとき（起動時に埋め込まれた文書、または『開く』で選んだ .json） | I7: 読み込んだファイルの中身が、決められた形に合いません | J7: 書き出したときのファイルをそのまま開いてください | K7: The contents of the file that was read do not match the settled shape → Open the file as it was written out | L7: 『開く』で黙って開かないのは不具合に見える。起動時と同じく告げる（acceptedIntake で RS-25 も通知する） | M7: NT-1 | N7: 表示する（今のまま） | P7: 表示する（今のまま） | Q7: ⚠️ 『開く』では何も出ずに開かない（出なさすぎ、2026-10-07 から変わらず） | R7: 起動時のみ src/framework/single-html-shell/single-html-shell.ts:285→645。『開く』の経路は document-file-flow.ts:316 が RS-64/RS-67 しか通知しないので黙る
A8: 7 | B8: RS-26 | C8: ファイル読込（開く・取り込み・起動時） | D8: エラー | E8: 要 | F8: D | G8: 既存 | H8: OS から「GRS で開く」で渡したファイルが起動時に読めなかったとき | I8: 起動時に渡されたファイルを読めなかったので、開いていません | J8: そのファイルを選び直して開いてください | K8: The file handed at start-up could not be read, so it was not opened → Choose that file again and open it | L8: 起動したのに文書が出ない理由が分からないので要る | M8: NT-1 | N8: 表示する（今のまま） | P8: 表示する（今のまま） | Q8: 起動時の用件として 1 枚に集約される（NT-4、notices.ts:220） | R8: src/framework/single-html-shell/single-html-shell.ts:287→645
A9: 8 | B9: RS-75 | C9: ファイル読込（開く・取り込み・起動時） | D9: エラー | E9: 要 | F9: H | G9: 新規 | H9: ヘッダーの『開く』や開き直す操作（Ctrl+R 相当の SK-21）が、権限・形式以外の思いがけない理由で途中で失敗したとき | I9: ファイルを開く途中で、思いがけない理由で失敗しました | J9: もう一度開いてください。続くときは、直前の操作を控えてください | K9: Opening the file failed partway for an unexpected reason → Open it once more; if it keeps happening, note what you did | L9: 開けなかったことは画面に出ないので要る。RS-15 より何が失敗したかが分かる分よい | M9: NT-3a | N9: 表示する（今のまま） | P9: 表示する（今のまま） | Q9: CR-705 で新設。RS-15 の「読む操作」版 | R9: src/framework/single-html-shell/document-file-flow.ts:491（beginReadingDocumentFile の catch）
A10: 9 | B10: RS-64 | C10: ファイル読込（開く・取り込み・起動時） | D10: エラー | E10: 要 | F10: E | G10: 既存 | H10: 新しい版の GRS で作った文書を『開く』で選んだ（または起動した）が、日程データの形がこの版で読めないとき | I10: この文書は新しい形式で書かれており、この版では開けません | J10: 最新版を {downloadUrl} からダウンロードして開いてください | K10: This document is in a newer format, and this version cannot open it → Download the latest version from {downloadUrl} and open the document there | L10: 開けない理由と最新版の入手先は告げないと分からない | M10: NT-1 | N10: 表示する（今のまま） | P10: 表示する（今のまま） | Q10: リンク {downloadUrl} 付き | R10: src/framework/single-html-shell/document-file-flow.ts:317／起動時 single-html-shell.ts:294
A11: 10 | B11: RS-48 | C11: ファイル読込（開く・取り込み・起動時） | D11: エラー | E11: 要 | F11: E | G11: 既存 | H11: 新しい版の GRS で作った文書を開き、この版で読めない項目があったとき | I11: この文書は新しい形式で書かれており、読めなかった項目があります | J11: 続けると、読めなかった項目は保存したときに失われます。失いたくないときは、最新版を {downloadUrl} からダウンロードして開いてください | K11: This document is in a newer format, and some items could not be read → If you go on, what could not be read is lost when you save. To keep it, download the latest version from {downloadUrl} and open the document there | L11: 保存すると読めなかった項目が失われる。データが消える話なので要る | M11: NT-1 | N11: 表示する（今のまま） | P11: 表示する（今のまま） | Q11: spec は NT-1（開く前に問う）だが src は開いた後に出す（DEVIATION DFC-855、document-file-flow.ts:336）。差分確認の画面（U-61）にも同じ語 | R11: src/framework/single-html-shell/document-file-flow.ts:338／起動時 single-html-shell.ts:651
A12: 11 | B12: RS-63 | C12: ファイル読込（開く・取り込み・起動時） | D12: 警告 | E12: 要 | F12: E | G12: 既存 | H12: 新しい版の GRS で作った文書を開き、すべての項目が読めたとき | I12: この文書は、この版より新しい形式で書かれています | J12: 最新版を {downloadUrl} からダウンロードして使ってください | K12: This document is in a newer format than this version → Download the latest version from {downloadUrl} and use it | L12: 失うものは無く、最新版の案内だけなので、読めれば足りる | M12: NT-5 | N12: OK を押さずに自然に消える表示にする | P12: OK を押さずに自然に消える表示にする | Q12: 開けて何も失われないのに OK を求める | R12: src/framework/single-html-shell/document-file-flow.ts:335／起動時 single-html-shell.ts:651
A13: 12 | B13: RS-14 | C13: ファイル読込（開く・取り込み・起動時） | D13: 警告 | E13: 要 | F13: I | G13: 既存 | H13: ヘッダーの『開く』で複数のファイルを選んだ、または複数を一度にドロップしたとき（先頭の 1 つだけ開く） | I13: 先頭の 1 つだけを開きました。残りは開いていません | J13: 残りは 1 つずつ開いてください | K13: Only the first file was opened; the rest were left → Open the rest one at a time | L13: 1 回の読込で出る知らせ（クラスタ I）を 1 枚の「読込の結果」にまとめ、件数の行として並べる | M13: NT-5 | N13: 1 枚にまとめる（同じまとまりの他の行と） | P13: 1 枚にまとめる（同じまとまりの他の行と） | Q13: 件数付き。同じ読込で RS-51/52/60/16/71/72 と積み重なり得る | R13: src/framework/single-html-shell/document-file-flow.ts:667
A14: 13 | B14: RS-50 | C14: ファイル読込（開く・取り込み・起動時） | D14: 警告 | E14: 要 | F14: I | G14: 既存 | H14: 使えない日付（読めない・範囲外）を持つタスクを含むファイルを開き、そのタスクを落として取り込んだとき | I14: 下記の無効なタスクを削除して取り込みました | J14: 元のファイルの日付を直して読み直すか、取り消しで取り込む前へ戻せます | K14: The invalid tasks listed below were removed, and the rest was imported → Fix the dates in the original file and read it again, or undo to get back to before the import | L14: タスクが消えたことと名前は画面からは分からない。I の他の行をまとめる受け皿にもなる | M14: NT-5 | N14: 表示する（今のまま） | P14: 表示する（今のまま） | Q14: 通知の欄ではなく取込報告の面に、落としたタスク名の一覧と出る。RS-73 と同じ面 | R14: src/adapter/screen-renderer/open-modals.ts:86（取込報告の面 U-62、OK で閉じる open-modals-drawing.ts:751）
A15: 14 | B15: RS-51 | C15: ファイル読込（開く・取り込み・起動時） | D15: 警告 | E15: 要 | F15: I | G15: 既存 | H15: 開いた文書（または起動時の文書）の設定値が範囲の外で、範囲内に収めたとき | I15: 読んだ設定値が範囲の外だったので、範囲に収めました | J15: 元の値が要るときは、保存し直す前に元のファイルを控えてください | K15: Settings the document carried were out of range and were brought back in → Keep a copy of the original file before saving, if those values matter | L15: 同じ読込の他の知らせと 1 枚（取込報告 U-62 か 1 枚の通知）に件数の行として並べる | M15: NT-5 | N15: 1 枚にまとめる（同じまとまりの他の行と） | P15: 1 枚にまとめる（同じまとまりの他の行と） | Q15: 件数付き | R15: src/framework/single-html-shell/document-file-flow.ts:798／起動時 single-html-shell.ts:647
A16: 15 | B16: RS-52 | C16: ファイル読込（開く・取り込み・起動時） | D16: 警告 | E16: 要 | F16: I | G16: 既存 | H16: 開いた文書の完了率が日付と食い違っていて数え直したとき、または『休日の設定』の『適用』などで暦を変えて完了率が変わったとき | I16: 完了率を日付から数え直しました | J16: 暦を変えたときは、取り消しで暦ごと戻せます。ファイルを開いたときは、元の値が日付と食い違っていました | K16: The percent complete was counted again from the dates → After a calendar change, Undo puts both back. After opening a file, its stored values disagreed with its dates | L16: 読込時は他の読込の知らせと 1 枚にまとめる。暦の編集後に単独で出る場合はそのまま 1 枚 | M16: NT-3 | N16: 1 枚にまとめる（同じまとまりの他の行と） | P16: 1 枚にまとめる（同じまとまりの他の行と） | Q16: 件数付き（NT-3）。画面の編集後にも出る | R16: src/framework/single-html-shell/document-file-flow.ts:799, 833／編集後 frame-loop.ts:3141
A17: 16 | B17: RS-60 | C17: ファイル読込（開く・取り込み・起動時） | D17: 警告 | E17: 要 | F17: I | G17: 既存 | H17: MSPDI XML を開き、1 つしか置けない要素が重なっていて最初のものを採ったとき | I17: 同じ要素が重なっていたので、最初のものを採りました | J17: 後のほうの値が正しいときは、元のファイルを直して読み直してください | K17: Some elements appeared more than once; the first of each was kept → If a later copy held the right value, fix the original file and read it again | L17: 同じ読込の他の知らせと 1 枚にまとめる | M17: NT-5 | N17: 1 枚にまとめる（同じまとまりの他の行と） | P17: 1 枚にまとめる（同じまとまりの他の行と） | Q17: 件数付き | R17: src/framework/single-html-shell/document-file-flow.ts:800
A18: 17 | B18: RS-71 | C18: ファイル読込（開く・取り込み・起動時） | D18: 警告 | E18: 要 | F18: I | G18: 新規 | H18: 『開く』→ ファイルを開く面で『合流させる』を選び、取り込んだファイルの値で対応するタスクを上書きしたとき | I18: 取り込んだファイルの値で、対応するタスクを上書きしました | J18: 上書きしたくなかったときは、取り消しで合流する前へ戻せます | K18: The matching tasks were overwritten with the values of the file you brought in → If that was not wanted, undo to get back to before the merge | L18: 合流の結果（上書き N 件・残した N 件・届かなかった名前）を 1 枚にまとめる。取り消しで戻せるので単独の OK は重い | M18: NT-3 | N18: 1 枚にまとめる（同じまとまりの他の行と） | P18: 1 枚にまとめる（同じまとまりの他の行と） | Q18: CR-688 で新設（MG-14）。件数付き。合流のたびに RS-72 と並んで出得る | R18: src/framework/single-html-shell/document-file-flow.ts:604（tellImportReport）
... A21: 20 | B21: RS-16 | C21: ファイル読込（開く・取り込み・起動時） | D21: 警告 | E21: 要 | F21: I | G21: 既存 | H21: ヘッダーの『変更前の予定』または開く面の『重ねる』で比較用のファイルを重ね、対応するタスクが無いものがあったとき | I21: 重ねたファイルの一部のタスクは、現在の文書に対応するものが無いので描いていません | J21: 対応するタスクを持つ文書へ重ねると描かれます | K21: Some tasks of the overlaid file have no counterpart in this document, so they are not drawn → Overlay it on a document that holds the matching tasks and they will be drawn | L21: 同じ読込で出る RS-51/52/60 などと 1 枚にまとめる | M21: NT-5 | N21: 1 枚にまとめる（同じまとまりの他の行と） | P21: 1 枚にまとめる（同じまとまりの他の行と） | Q21: 件数付き | R21: src/framework/single-html-shell/document-file-flow.ts:601（tellImportReport）
A22: 21 | B22: RS-21 | C22: ファイル読込（開く・取り込み・起動時） | D22: エラー | E22: 要 | G22: 既存 | H22: 稼働する曜日が 1 つも無い暦を持つ文書を『開く』で選んだ、または起動したとき | I22: 稼働する曜日が 1 つも無い暦なので、この文書の暦にできません | J22: 稼働する曜日を 1 つ以上選んでください | K22: This calendar has no working weekday, so it cannot be the calendar of this document → Choose at least one working weekday | L22: 開けない理由と直し方は画面に出ないので要る | M22: NT-1 | N22: 表示する（今のまま） | P22: 表示する（今のまま） | Q22: IV-17 と同じ条件（クラスタ M）。『休日の設定』で全曜日を休みにする編集は REFUSAL_SITUATIONS（frame-loop.ts:905）に IV-17 が無いので RS-10 になる見込み（未実測） | R22: src/framework/single-html-shell/document-file-flow.ts:724／起動時 single-html-shell.ts:347
A23: 22 | B23: QN-5 | C23: ファイル読込（開く・取り込み・起動時） | D23: 確認 | E23: 要 | F23: L | G23: 既存 | H23: ヘッダーの『開く』で『置き換える』を選んだとき、または『新規作成』を押したとき（いまの文書を捨てる前） | I23: いまの文書を閉じますか？ 保存していない編集と、元に戻す履歴は失われます | K23: Close the current document? Unsaved edits and the undo history will be lost | L23: 未保存の編集が無いときは失うのは取り消しの履歴だけなので問わない（未保存の編集があるときだけ今のまま問う） | M23: NT-7 | N23: 表示しない | P23: 表示しない | Q23: 未保存の編集の有無によらず問う（spec 表 T-234 が明記）。Yes / No、y / n、Esc = No | R23: src/framework/single-html-shell/frame-loop.ts:2147（discardQuestionOf）, 3200（新規作成）
A24: 23 | B24: IV-1 | C24: ファイル読込 — 取り込みの拒否（不変条件 表 T-220） | D24: エラー | E24: — | F24: M | G24: 既存 | H24: 開いたファイルの中で ID（主キー）が重複しているとき | L24: 案「同じ ID のものが 2 つ以上あるので、このファイルは開けません → 元のファイルの ID の重なりを直してから開いてください」（RS-57 と語を揃える） | N24: 文面を直す（コメントに案） | P24: 文面を直す（コメントに案） | Q24: 語が空で、今は何も出ずに開かない。編集での同じ拒否は RS-57（frame-loop.ts:909） | R24: なし（schedule-invariants.ts:323 が検査。取込の拒否は document-file-flow.ts:717 で黙って false、frame-loop.ts:895 importRefused: null）
A25: 24 | B25: IV-2 | C25: ファイル読込 — 取り込みの拒否（不変条件 表 T-220） | D25: エラー | E25: — | G25: 既存 | H25: 開いたファイルの参照先（外部キー: タスク・担当者・タスクグループの id）が存在しないとき | L25: 案「存在しないものを指している参照があるので、このファイルは開けません → 書き出したときのファイルをそのまま開いてください」 | N25: 文面を直す（コメントに案） | P25: 文面を直す（コメントに案） | Q25: 語が空。編集での同じ拒否（edit-task.ts:205 など）は REFUSAL_SITUATIONS に無いので RS-10 になる | R25: なし（schedule-invariants.ts:347。取込は document-file-flow.ts:717 で黙る）
A26: 25 | B26: IV-3 | C26: ファイル読込 — 取り込みの拒否（不変条件 表 T-220） | D26: エラー | E26: — | G26: 既存 | H26: 開いたファイルで、ピン止めしたタスクグループ（行）が存在しないものを指しているとき | L26: 案「ピン止めの記録が存在しないタスクグループを指しているので、このファイルは開けません → 書き出したときのファイルをそのまま開いてください」 | N26: 文面を直す（コメントに案） | P26: 文面を直す（コメントに案） | Q26: 語が空 | R26: なし（schedule-invariants.ts:385。取込は document-file-flow.ts:717 で黙る）
A27: 26 | B27: IV-4 | C27: ファイル読込 — 取り込みの拒否（不変条件 表 T-220） | D27: エラー | E27: — | F27: M | G27: 既存 | H27: 開いたファイルのタスクの親子（WBS の親）が輪になっているとき | L27: 案「タスクの親子が輪になっているので、このファイルは開けません → 元のファイルで親子の輪を解いてから開いてください」 | N27: 文面を直す（コメントに案） | P27: 文面を直す（コメントに案） | Q27: 語が空。RS-55（輪）と近い | R27: なし（schedule-invariants.ts:403。取込は document-file-flow.ts:717 で黙る）
A28: 27 | B28: IV-5 | C28: ファイル読込 — 取り込みの拒否（不変条件 表 T-220） | D28: エラー | E28: — | G28: 既存 | H28: 開いたファイルのタスクグループ（行）の入れ子が深さの上限を超えているとき | L28: 案「タスクグループの入れ子が段の上限より深いので、このファイルは開けません → 元のファイルで入れ子を浅くしてから開いてください」 | N28: 文面を直す（コメントに案） | P28: 文面を直す（コメントに案） | Q28: 語が空 | R28: なし（schedule-invariants.ts:419。取込は document-file-flow.ts:717 で黙る）
A29: 28 | B29: IV-6 | C29: ファイル読込 — 取り込みの拒否（不変条件 表 T-220） | D29: エラー | E29: — | G29: 既存 | H29: 開いたファイルで、タスクがどのタスクグループ（行）にも属していない、または 2 つ以上に属しているとき | L29: 案「どのタスクグループにも載っていない（または 2 つ以上に載っている）タスクがあるので、このファイルは開けません → 書き出したときのファイルをそのまま開いてください」 | N29: 文面を直す（コメントに案） | P29: 文面を直す（コメントに案） | Q29: 語が空 | R29: なし（schedule-invariants.ts:443。取込は黙る。編集 edit-task.ts:301 は RS-10）
A30: 29 | B30: IV-23 | C30: ファイル読込 — 取り込みの拒否（不変条件 表 T-220） | D30: エラー | E30: — | G30: 既存 | H30: 開いたファイルで、タスクの見た目の記録が 0 個または 2 個以上あるとき | L30: 案「タスクの見た目の記録が欠けているか重なっているので、このファイルは開けません → 書き出したときのファイルをそのまま開いてください」 | N30: 文面を直す（コメントに案） | P30: 文面を直す（コメントに案） | Q30: 語が空 | R30: なし（validate-imported-document.ts:313 が検査し、document-file-flow.ts:717 で黙って開かない）
A31: 30 | B31: IV-7 | C31: ファイル読込 — 取り込みの拒否（不変条件 表 T-220） | D31: エラー | E31: — | G31: 既存 | H31: 開いたファイルに暦が 1 つも無いとき | L31: 案「暦が 1 つも無いので、このファイルは開けません → 書き出したときのファイルをそのまま開いてください」 | N31: 文面を直す（コメントに案） | P31: 文面を直す（コメントに案） | Q31: 語が空 | R31: なし（schedule-invariants.ts:455。取込は黙る）
A32: 31 | B32: IV-17 | C32: ファイル読込 — 取り込みの拒否（不変条件 表 T-220） | D32: エラー | E32: — | F32: M | G32: 既存 | H32: 開いたファイルの暦に稼働する曜日が 1 つも無いとき | L32: 案: RS-21 の語をそのまま使う（「稼働する曜日が 1 つも無い暦なので…」）。IV-17 独自の語は要らない | N32: 文面を直す（コメントに案） | P32: 文面を直す（コメントに案） | Q32: 語が空。RS-21 と同じ条件で、画面には RS-21 が出る | R32: なし（schedule-invariants.ts:473。ただし開く経路では先に RS-21 が出る document-file-flow.ts:722-725）
A33: 32 | B33: IV-8 | C33: ファイル読込 — 取り込みの拒否（不変条件 表 T-220） | D33: エラー | E33: — | G33: 既存 | H33: 開いたファイルで、タスクグループ（行）が名前も元タスクも持たないとき | L33: 案「名前の無いタスクグループがあるので、このファイルは開けません → 書き出したときのファイルをそのまま開いてください」 | N33: 文面を直す（コメントに案） | P33: 文面を直す（コメントに案） | Q33: 語が空 | R33: なし（schedule-invariants.ts:486。取込は黙る）
A34: 33 | B34: IV-9 | C34: ファイル読込 — 取り込みの拒否（不変条件 表 T-220） | D34: エラー | E34: — | G34: 既存 | H34: 開いたファイルで、タスクや注記の塗りと線が両方とも透明のとき（プロパティパネルで両方を透明にする編集も同じ拒否） | L34: 案「塗りと線の両方を透明にはできません → どちらかに色を付けてください」（取込では「…ものがあるので、このファイルは開けません」） | N34: 文面を直す（コメントに案） | P34: 文面を直す（コメントに案） | Q34: 語が空 | R34: なし（schedule-invariants.ts:503。編集 task-appearance.ts:125・edit-annotation.ts:366 は RS-10 になる）
A35: 34 | B35: IV-10 | C35: ファイル読込 — 取り込みの拒否（不変条件 表 T-220） | D35: エラー | E35: — | F35: M | G35: 既存 | H35: 開いたファイルで、タスクの終了日が開始日より前のとき | L35: 案: RS-58 の語に「…タスクがあるので、このファイルは開けません」を付けて使う | N35: 文面を直す（コメントに案） | P35: 文面を直す（コメントに案） | Q35: 語が空。RS-58 と同じ条件 | R35: なし（schedule-invariants.ts:529。取込は黙る。編集では RS-58）
A36: 35 | B36: IV-11 | C36: ファイル読込 — 取り込みの拒否（不変条件 表 T-220） | D36: エラー | E36: — | G36: 既存 | H36: 開いたファイルで、フェードを持つタスクに終了日が無いとき（編集でフェードを付ける場合も） | L36: 案「終了日の無いタスクにはフェードを付けられません → 終了日を入れてから付けてください」 | N36: 文面を直す（コメントに案） | P36: 文面を直す（コメントに案） | Q36: 語が空 | R36: なし（schedule-invariants.ts:549。編集 task-appearance.ts:62 は RS-10）
A37: 36 | B37: IV-12 | C37: ファイル読込 — 取り込みの拒否（不変条件 表 T-220） | D37: エラー | E37: — | G37: 既存 | H37: 開いたファイルで、フェードの日数の和がタスクの期間を超えるとき（プロパティパネルでフェードを長くしすぎた場合も） | L37: 案「フェードの日数の和が、タスクの期間より長くなっています → フェードを短くするか、期間を延ばしてください」 | N37: 文面を直す（コメントに案） | P37: 文面を直す（コメントに案） | Q37: 語が空 | R37: なし（schedule-invariants.ts:567。編集 task-appearance.ts:68・task-plan-actual.ts:311 は RS-10）
A38: 37 | B38: IV-14 | C38: ファイル読込 — 取り込みの拒否（不変条件 表 T-220） | D38: エラー | E38: — | G38: 既存 | H38: 開いたファイルの日付の列が日付として読めない／扱える範囲の外のとき（プロパティパネルで範囲外の日付を入れた場合も） | L38: 案「日付として読めない値か、扱える範囲の外の日付です → 正しい日付を入れてください」（編集の拒否で RS-10 に潰れないように） | N38: 文面を直す（コメントに案） | P38: 文面を直す（コメントに案） | Q38: 語が空。取込では RS-50 が代わりに出る | R38: なし（取込では該当タスクを落として RS-50 になる document-file-flow.ts:341。編集 task-create.ts:32 などは RS-10）
A39: 38 | B39: IV-15 | C39: ファイル読込 — 取り込みの拒否（不変条件 表 T-220） | D39: エラー | E39: — | G39: 既存 | H39: 開いたファイルの取込の通番が文書の通番を超えるとき | L39: 案「ファイルの中の取り込みの記録が食い違っているので、このファイルは開けません → 書き出したときのファイルをそのまま開いてください」 | N39: 文面を直す（コメントに案） | P39: 文面を直す（コメントに案） | Q39: 語が空。内部の数 | R39: なし（schedule-invariants.ts:633。取込は黙る）
A40: 39 | B40: IV-16 | C40: ファイル読込 — 取り込みの拒否（不変条件 表 T-220） | D40: エラー | E40: — | G40: 既存 | H40: 開いたファイルの設定値が、別の設定値との上下の関係を満たさないとき | L40: 案「設定値の上限と下限が逆になっているので、このファイルは開けません → 元のファイルの設定値を直してから開いてください」 | N40: 文面を直す（コメントに案） | P40: 文面を直す（コメントに案） | Q40: 語が空。範囲外の単独値は RS-51 で収めて開くのに、上下の逆転は黙って開かない | R40: なし（schedule-invariants.ts:652。取込は黙る）
A41: 40 | B41: IV-19 | C41: ファイル読込 — 取り込みの拒否（不変条件 表 T-220） | D41: エラー | E41: — | F41: M | G41: 既存 | H41: 開いたファイルで、注記（ハイライトボックス）の開始と終了、上と下が逆のとき | L41: 案「始まりと終わり（または上と下）が逆のハイライトボックスがあるので、このファイルは開けません」 | N41: 文面を直す（コメントに案） | P41: 文面を直す（コメントに案） | Q41: 語が空。RS-58 の注記版 | R41: なし（schedule-invariants.ts:678。取込は黙る）
A42: 41 | B42: IV-18 | C42: ファイル読込 — 取り込みの拒否（不変条件 表 T-220） | D42: エラー | E42: — | F42: M | G42: 既存 | H42: 開いたファイルのタスクグループ（行）の親子が輪になっているとき | L42: 案「タスクグループの親子が輪になっているので、このファイルは開けません → 書き出したときのファイルをそのまま開いてください」 | N42: 文面を直す（コメントに案） | P42: 文面を直す（コメントに案） | Q42: 語が空。RS-55（輪）と近い | R42: なし（schedule-invariants.ts:701。取込は黙る）
...

Sheet まとまり
A1: まとまり | B1: 中身（2026-10-07 の一覧から。新規の行はシート『記入』の列で確かめた） | C1: 行数
A2: A | B2: 「この変更は適用できません」 —— RS-6 / RS-7 / RS-8 / RS-9 / RS-10（次の一手がすべて「…もう一度行ってください」）。RS-15・RS-27 も同じ型 | C2: =COUNTIF(記入!$F$2:$F$139,A2) -> 6
A3: B | B3: 「対象が無い・押しても何も起きない」 —— RS-27 / RS-28 / RS-29 / RS-30 / RS-31 / RS-32 / RS-33 / RS-34（次の一手がすべて「…もう一度押してください」） | C3: =COUNTIF(記入!$F$2:$F$139,A3) -> 8
A4: C | B4: 「これ以上動かせません」 —— RS-36 / RS-37 / RS-38 / RS-39 / RS-46（RS-38 と RS-46 は同じ深さの上限） | C4: =COUNTIF(記入!$F$2:$F$139,A4) -> 5
A5: D | B5: 「このファイルは読めません」 —— RS-4 / RS-11 / RS-12 / RS-13 / RS-25 / RS-67（＋RS-26） | C5: =COUNTIF(記入!$F$2:$F$139,A5) -> 7
A6: E | B6: 「新しい形式の文書」 —— RS-48 / RS-63 / RS-64（同じ {downloadUrl} の次の一手） | C6: =COUNTIF(記入!$F$2:$F$139,A6) -> 3
A7: F | B7: 「保存先を選んで書き出してください」 —— RS-2 / RS-5（次の一手が同文）、RS-3 / RS-40（ほぼ同文） | C7: =COUNTIF(記入!$F$2:$F$139,A7) -> 4
A8: G | B8: 「描けない・収まらない」 —— RS-22 / RS-43（次の一手が同文）、RS-24 | C8: =COUNTIF(記入!$F$2:$F$139,A8) -> 2
A9: H | B9: 「原因不明の失敗」 —— RS-15 / RS-42 | C9: =COUNTIF(記入!$F$2:$F$139,A9) -> 4
A10: I | B10: 「読込時に自動で直した」 —— RS-50 / RS-51 / RS-52 / RS-60（＋RS-14・RS-16。1 回の読込で積み重なる） | C10: =COUNTIF(記入!$F$2:$F$139,A10) -> 9
A11: J | B11: 「クリップボードへコピーしました」 —— RS-65 / RS-68 | C11: =COUNTIF(記入!$F$2:$F$139,A11) -> 2
A12: K | B12: 削除の確認 —— QN-1 / QN-2 / QN-10 / QN-3 | C12: =COUNTIF(記入!$F$2:$F$139,A12) -> 5
A13: L | B13: 「失われます」の確認 —— QN-4 / QN-5 / QN-11 / QN-8 | C13: =COUNTIF(記入!$F$2:$F$139,A13) -> 4
... A16: O | B16: 遅延診断の所見 —— VC-15 / VS-4（予定版と実績版）、VC-5 / VC-6（実績開始が無い）、VC-11 / VC-12（親の両端） | C16: =COUNTIF(記入!$F$2:$F$139,A16) -> 6

Sheet 退役・変化
A1: 2026-10-07 の一覧からの変化
A2: RS-71 新規（CR-688、表 T-032 の MG-14）: 『合流させる』で取り込んだ値でタスクを上書きしたとき、件数付きの警告（NT-3）。document-file-flow.ts:604
A3: RS-72 新規（CR-688、MG-14）: 『合流させる』で取込側に無かったタスクを残したとき、件数付きの警告（NT-5）。旧一覧の MG-7（語なし）を置き換える。document-file-flow.ts:606
A4: RS-73 新規（CR-688、MG-14）: 前回は届いて今回届かなかったタスクを名前で並べる（NT-5）。通知の欄ではなく RS-50 と同じ取込報告の面 U-62。旧一覧の MG-11（語なし）を置き換える。open-modals.ts:88
A5: RS-74 新規（CR-692）: 確認の問いが立っている間の Agent API の書き込みの拒否理由（NT-1）。画面には出ない（画面からの同じ拒否は RS-27）
A6: RS-75 新規（CR-705）: ファイルを開く・開き直す操作が思いがけない理由で途中で失敗したとき（NT-3a）。document-file-flow.ts:491
A7: RS-76 新規（CR-705）: 保存・書き出しが思いがけない理由で途中で失敗したとき、ファイルに書けていないかもしれないと告げる（NT-3a）。document-file-flow.ts:507
A8: QN-13 退役（CR-701、JDG-1610）: 非稼働日に端を置いたときの問いをやめた。表 T-234 は 11 → 10 行
A9: MG-7・MG-11 退役（一覧の行として）: 語が RS-72・RS-73 にできたので「辞書に語も src も無い通知」から外れた。残るのは MG-10・EX-3 と FR-100
A10: 文面変更: 0 件（既存の RS / QN / IV / 状態文 / 遅延診断の語は a9cdba5b から 1 文字も変わっていない）
A11: 領域名の変更: 「行の階層・移動」→「タスクグループの階層・移動」（JDG-1570。ただし画面の語の改名 CR-708 は下書きで、メッセージの文はまだ「行」）
A13: 退役した行（記入は不要。参考）
... A27: 7. 面の名前は display-words.json と仕様の今の語で書いた。改名「行 → タスクグループ」は CR-708 が下書き（当てていない）なので、利用者に見える文はまだ「行」。場面の欄では「タスクグループ（行）」と併記し、領域名だけ「タスクグループの階層・移動」に改めた。
